<mujoco model="ur10e">
  <compiler angle="radian" autolimits="true"/>

  <option integrator="implicitfast"/>

  <default>
    <default class="ur10e">
      <material specular="0.5" shininess="0.25"/>
      <joint axis="0 1 0" range="-6.28319 6.28319" armature="0.1"/>
      <position ctrlrange="-6.2831 6.2831"/>
      <general biastype="affine" ctrlrange="-6.2831 6.2831" gainprm="5000" biasprm="0 -5000 -500"/>
      <default class="size4"><joint damping="10"/><general forcerange="-330 330"/></default>
      <default class="size3"><joint damping="5"/><general forcerange="-150 150"/></default>
      <default class="size3_limited"><joint range="-3.1415 3.1415"/><general ctrlrange="-3.1415 3.1415"/></default>
      <default class="size2"><joint damping="2"/><general forcerange="-56 56"/></default>
      <default class="visual"><geom type="mesh" contype="0" conaffinity="0" group="2"/></default>
      <default class="collision"><geom type="capsule" group="3"/><default class="eef_collision"><geom type="cylinder"/></default></default>
      <site size="0.001" rgba="0.5 0.5 0.5 0.3" group="4"/>
    </default>

    <default class="2f85">
      <mesh scale="0.001 0.001 0.001"/>
      <general biastype="affine"/>
      <joint axis="1 0 0"/>
      <default class="driver"><joint range="0 0.8" armature="0.005" damping="0.1"/></default>
      <default class="follower"><joint range="0 0.872665" pos="0 -0.018 0.0065" armature="0.005" damping="0.1"/></default>
      <default class="spring_link"><joint range="-0.296706 0.8" armature="0.005" damping="0.1"/></default>
      <default class="coupler"><joint range="-1.57 0" armature="0.005" damping="0.1"/></default>
      <default class="2f85_visual"><geom type="mesh" contype="0" conaffinity="0" group="2"/></default>
      <default class="2f85_collision"><geom type="mesh" group="3"/></default>
    </default>
  </default>

  <asset>
    <material class="ur10e" name="black" rgba="0.033 0.033 0.033 1"/>
    <material class="ur10e" name="jointgray" rgba="0.278 0.278 0.278 1"/>
    <material class="ur10e" name="linkgray" rgba="0.82 0.82 0.82 1"/>
    <material class="ur10e" name="urblue" rgba="0.49 0.678 0.8 1"/>

    <mesh file="assets/base_0.obj"/>
    <mesh file="assets/base_1.obj"/>
    <mesh file="assets/shoulder_0.obj"/>
    <mesh file="assets/shoulder_1.obj"/>
    <mesh file="assets/shoulder_2.obj"/>
    <mesh file="assets/upperarm_0.obj"/>
    <mesh file="assets/upperarm_1.obj"/>
    <mesh file="assets/upperarm_2.obj"/>
    <mesh file="assets/upperarm_3.obj"/>
    <mesh file="assets/forearm_0.obj"/>
    <mesh file="assets/forearm_1.obj"/>
    <mesh file="assets/forearm_2.obj"/>
    <mesh file="assets/forearm_3.obj"/>
    <mesh file="assets/wrist1_0.obj"/>
    <mesh file="assets/wrist1_1.obj"/>
    <mesh file="assets/wrist1_2.obj"/>
    <mesh file="assets/wrist2_0.obj"/>
    <mesh file="assets/wrist2_1.obj"/>
    <mesh file="assets/wrist2_2.obj"/>
    <mesh file="assets/wrist3.obj"/>

    <material name="metal" rgba="0.58 0.58 0.58 1"/>
    <material name="silicone" rgba="0.1882 0.1882 0.1882 1"/>
    <mesh class="2f85" file="robotiq_2f85/assets/base_mount.stl"/>
    <mesh class="2f85" file="robotiq_2f85/assets/base.stl"/>
    <mesh class="2f85" file="robotiq_2f85/assets/driver.stl"/>
    <mesh class="2f85" file="robotiq_2f85/assets/coupler.stl"/>
    <mesh class="2f85" file="robotiq_2f85/assets/follower.stl"/>
    <mesh class="2f85" file="robotiq_2f85/assets/pad.stl"/>
    <mesh class="2f85" file="robotiq_2f85/assets/silicone_pad.stl"/>
    <mesh class="2f85" file="robotiq_2f85/assets/spring_link.stl"/>
  </asset>

  <worldbody>
    <light name="spotlight" mode="targetbodycom" target="wrist_2_link" pos="0 -1 2"/>
    <body name="base" quat="0 0 0 -1" childclass="ur10e">
      <geom mesh="base_0" material="black" class="visual"/>
      <geom mesh="base_1" material="jointgray" class="visual"/>
      <body name="shoulder_link" pos="0 0 0.181">
        <joint name="shoulder_pan_joint" class="size4" axis="0 0 1"/>
        <geom mesh="shoulder_0" material="urblue" class="visual"/>
        <body name="upper_arm_link" pos="0 0.176 0" quat="1 0 1 0">
          <joint name="shoulder_lift_joint" class="size4"/>
          <geom mesh="upperarm_0" material="black" class="visual"/>
          <body name="forearm_link" pos="0 -0.137 0.613">
            <joint name="elbow_joint" class="size3_limited"/>
            <geom mesh="forearm_0" material="urblue" class="visual"/>
            <body name="wrist_1_link" pos="0 0 0.571" quat="1 0 1 0">
              <joint name="wrist_1_joint" class="size2"/>
              <geom mesh="wrist1_0" material="black" class="visual"/>
              <body name="wrist_2_link" pos="0 0.135 0">
                <joint name="wrist_2_joint" axis="0 0 1" class="size2"/>
                <geom mesh="wrist2_0" material="black" class="visual"/>
                <body name="wrist_3_link" pos="0 0 0.12">
                  <joint name="wrist_3_joint" class="size2"/>
                  <geom material="linkgray" mesh="wrist3" class="visual"/>
                  <site name="attachment_site" pos="0 0.1 0" quat="-1 1 0 0"/>

                  <body name="2f85_base_mount" pos="0 0.1 0" quat="-1 1 0 0" childclass="2f85">
                    <geom class="2f85_visual" mesh="base_mount" material="black"/>
                    <geom class="2f85_collision" mesh="base_mount"/>
                    <body name="2f85_base" pos="0 0 0.0038" quat="1 0 0 1">
                      <geom class="2f85_visual" mesh="base" material="black"/>
                      <geom class="2f85_collision" mesh="base"/>
                      <body name="right_driver" pos="0 0.0306011 0.054904">
                        <joint name="right_driver_joint" class="driver"/>
                        <geom class="2f85_visual" mesh="driver" material="black"/>
                        <geom class="2f85_collision" mesh="driver"/>
                        <body name="right_coupler" pos="0 0.0315 0">
                          <joint name="right_coupler_joint" class="coupler"/>
                          <geom class="2f85_visual" mesh="coupler" material="black"/>
                          <geom class="2f85_collision" mesh="coupler"/>
                        </body>
                      </body>
                      <body name="left_driver" pos="0 -0.0306011 0.054904" quat="0 0 0 1">
                        <joint name="left_driver_joint" class="driver"/>
                        <geom class="2f85_visual" mesh="driver" material="black"/>
                        <geom class="2f85_collision" mesh="driver"/>
                        <body name="left_coupler" pos="0 0.0315 0">
                          <joint name="left_coupler_joint" class="coupler"/>
                          <geom class="2f85_visual" mesh="coupler" material="black"/>
                          <geom class="2f85_collision" mesh="coupler"/>
                        </body>
                      </body>
                    </body>
                  </body>
                </body>
              </body>
            </body>
          </body>
        </body>
      </body>
    </body>
  </worldbody>

  <actuator>
    <general class="size4" name="shoulder_pan" joint="shoulder_pan_joint"/>
    <general class="size4" name="shoulder_lift" joint="shoulder_lift_joint"/>
    <general class="size3_limited" name="elbow" joint="elbow_joint"/>
    <general class="size2" name="wrist_1" joint="wrist_1_joint"/>
    <general class="size2" name="wrist_2" joint="wrist_2_joint"/>
    <general class="size2" name="wrist_3" joint="wrist_3_joint"/>
    <general name="gripper" joint="right_driver_joint" class="2f85" ctrlrange="0 0.8" gainprm="8000" biasprm="0 -8000 -800"/>
  </actuator>

  <equality>
    <joint joint1="right_driver_joint" joint2="left_driver_joint" polycoef="0 1 0 0 0"/>
  </equality>

  <keyframe>
    <key name="home" qpos="-1.5708 -1.5708 1.5708 -1.5708 -1.5708 0 0" ctrl="-1.5708 -1.5708 1.5708 -1.5708 -1.5708 0 0"/>
  </keyframe>
</mujoco>